<?xml version="1.0"?>
<robot name="double_link">

   <link name="my_ground">
    <inertial>
      <origin xyz="0 0 0" rpy="0 0 0"/>
      <mass value="1000"/>
      <inertia ixx="100000"  ixy="0"  ixz="0" iyy="100000" iyz="0" izz="100000" />
    </inertial>
   </link>

   <link name="link1">
    <inertial>
      <origin xyz="1.0 0 0" rpy="0 1.5707963267948966 0"/>
      <mass value="1"/>
      <inertia ixx="100"  ixy="0"  ixz="0" iyy="100" iyz="0" izz="100" />
    </inertial>
    <visual>
      <origin xyz="1.0 0 0" rpy="0 1.5707963267948966 0"/>
      <geometry>
        <cylinder radius="0.2" length="2"/>
      </geometry>
    </visual>
    <collision>
      <origin xyz="1.0 0 0" rpy="0 1.5707963267948966 0"/>
      <geometry>
        <cylinder radius="0.2" length="2"/>
      </geometry>
    </collision>
  </link>

   <link name="link2">
    <inertial>
      <origin xyz="1.0 0 0" rpy="0 1.5707963267948966 0"/>
      <mass value="1"/>
      <inertia ixx="100"  ixy="0"  ixz="0" iyy="100" iyz="0" izz="100" />
    </inertial>
    <visual>
      <origin xyz="1.0 0 0" rpy="0 1.5707963267948966 0"/>
      <geometry>
        <cylinder radius="0.2" length="2"/>
      </geometry>
    </visual>
    <collision>
      <origin xyz="1.0 0 0" rpy="0 1.5707963267948966 0"/>
      <geometry>
        <cylinder radius="0.2" length="2"/>
      </geometry>
    </collision>
  </link>

   <link name="obstacle1">
    <inertial>
      <origin xyz="0.0 0 0" rpy="0 0 0"/>
      <mass value="1"/>
      <inertia ixx="100"  ixy="0"  ixz="0" iyy="100" iyz="0" izz="100" />
    </inertial>
    <visual>
      <origin xyz="0.0 0 0" rpy="0 0 0"/>
      <geometry>
        <cylinder radius="0.4" length="2"/>
      </geometry>
      <material name="Cyan">
        <color rgba="0 1.0 1.0 1.0"/>
      </material>
    </visual>
    <collision>
      <origin xyz="0.0 0 0" rpy="0 0 0"/>
      <geometry>
        <cylinder radius="0.4" length="2"/>
      </geometry>
    </collision>
  </link>

   <link name="obstacle2">
    <inertial>
      <origin xyz="0.0 0 0" rpy="0 0 0"/>
      <mass value="1"/>
      <inertia ixx="100"  ixy="0"  ixz="0" iyy="100" iyz="0" izz="100" />
    </inertial>
    <visual>
      <origin xyz="0.0 0 0" rpy="0 0 0"/>
      <geometry>
        <cylinder radius="0.4" length="2"/>
      </geometry>
      <material name="Cyan">
        <color rgba="0 1.0 1.0 1.0"/>
      </material>
    </visual>
    <collision>
      <origin xyz="0.0 0 0" rpy="0 0 0"/>
      <geometry>
        <cylinder radius="0.4" length="2"/>
      </geometry>
    </collision>
  </link>

   <link name="obstacle3">
    <inertial>
      <origin xyz="0.0 0 0" rpy="0 0 0"/>
      <mass value="1"/>
      <inertia ixx="100"  ixy="0"  ixz="0" iyy="100" iyz="0" izz="100" />
    </inertial>
    <visual>
      <origin xyz="0.0 0 0" rpy="0 0 0"/>
      <geometry>
        <cylinder radius="0.4" length="2"/>
      </geometry>
      <material name="Cyan">
        <color rgba="0 1.0 1.0 1.0"/>
      </material>
    </visual>
    <collision>
      <origin xyz="0.0 0 0" rpy="0 0 0"/>
      <geometry>
        <cylinder radius="0.4" length="2"/>
      </geometry>
    </collision>
  </link>

   <joint name="joint_ground_link1" type="continuous">
     <parent link="my_ground"/>
     <child link="link1"/>
     <origin xyz="0 0 0" rpy="0 0 0" />
     <axis xyz="0.0 0.0 1.0" />
   </joint>

   <joint name="joint_link1_link2" type="continuous">
     <parent link="link1"/>
     <child link="link2"/>
     <origin xyz="2 0 0" rpy="0 0 0" />
     <axis xyz="0.0 0.0 1.0" />
   </joint>

   <joint name="joint_ground_obstacle1" type="fixed">
     <parent link="my_ground"/>
     <child link="obstacle1"/>
     <origin xyz="1 1 0" rpy="0 0 0" />
   </joint>

   <joint name="joint_ground_obstacle2" type="fixed">
     <parent link="my_ground"/>
     <child link="obstacle2"/>
     <origin xyz="1 3 0" rpy="0 0 0" />
   </joint>

   <joint name="joint_ground_obstacle3" type="fixed">
     <parent link="my_ground"/>
     <child link="obstacle3"/>
     <origin xyz="-1 3 0" rpy="0 0 0" />
   </joint>

 </robot>
